{
 "cells": [
  {
   "cell_type": "code",
   "execution_count": 1,
   "metadata": {},
   "outputs": [
    {
     "name": "stderr",
     "output_type": "stream",
     "text": [
      "/usr/lib/python3/dist-packages/requests/__init__.py:89: RequestsDependencyWarning: urllib3 (1.26.15) or chardet (3.0.4) doesn't match a supported version!\n",
      "  warnings.warn(\"urllib3 ({}) or chardet ({}) doesn't match a supported \"\n",
      "/usr/local/lib/python3.8/dist-packages/tqdm/auto.py:21: TqdmWarning: IProgress not found. Please update jupyter and ipywidgets. See https://ipywidgets.readthedocs.io/en/stable/user_install.html\n",
      "  from .autonotebook import tqdm as notebook_tqdm\n",
      "2023-04-19 11:16:23.083297: I tensorflow/core/platform/cpu_feature_guard.cc:182] This TensorFlow binary is optimized to use available CPU instructions in performance-critical operations.\n",
      "To enable the following instructions: AVX2 FMA, in other operations, rebuild TensorFlow with the appropriate compiler flags.\n"
     ]
    },
    {
     "name": "stdout",
     "output_type": "stream",
     "text": [
      "TensorSpec(shape=(124, 129), dtype=tf.float32, name=None)\n"
     ]
    },
    {
     "name": "stderr",
     "output_type": "stream",
     "text": [
      "2023-04-19 11:16:24.899226: I tensorflow/core/common_runtime/gpu/gpu_device.cc:1635] Created device /job:localhost/replica:0/task:0/device:GPU:0 with 7444 MB memory:  -> device: 0, name: NVIDIA GeForce RTX 3080, pci bus id: 0000:01:00.0, compute capability: 8.6\n"
     ]
    }
   ],
   "source": [
    "from get_dataset import * \n",
    "import matplotlib.pyplot as plt\n",
    "import numpy as np\n",
    "from tensorflow.keras import models, layers\n",
    "ds_test = get_dataset(\"test\")\n",
    "print(next(iter(ds_test.element_spec)))"
   ]
  },
  {
   "cell_type": "code",
   "execution_count": 2,
   "metadata": {},
   "outputs": [],
   "source": [
    "seed = 42\n",
    "tf.random.set_seed(seed)\n",
    "np.random.seed(seed)"
   ]
  },
  {
   "cell_type": "code",
   "execution_count": 3,
   "metadata": {},
   "outputs": [],
   "source": [
    "def my_map(x, y):\n",
    "    return x[..., tf.newaxis], y\n",
    "\n",
    "def my_filter(x, y):\n",
    "    return y < 10\n",
    "\n",
    "ds_train = get_dataset(\"train\").map(my_map).batch(64)\n",
    "ds_test = get_dataset(\"test\").map(my_map).batch(64)"
   ]
  },
  {
   "cell_type": "code",
   "execution_count": 4,
   "metadata": {},
   "outputs": [
    {
     "name": "stderr",
     "output_type": "stream",
     "text": [
      "2023-04-19 11:16:30.770070: I tensorflow/core/common_runtime/executor.cc:1197] [/device:CPU:0] (DEBUG INFO) Executor start aborting (this does not indicate an error and you can ignore this message): INVALID_ARGUMENT: You must feed a value for placeholder tensor 'Placeholder/_0' with dtype int32\n",
      "\t [[{{node Placeholder/_0}}]]\n"
     ]
    },
    {
     "data": {
      "text/plain": [
       "TensorShape([64, 124, 129, 1])"
      ]
     },
     "execution_count": 4,
     "metadata": {},
     "output_type": "execute_result"
    }
   ],
   "source": [
    "input_shape = next(iter(ds_train))[0].shape\n",
    "input_shape"
   ]
  },
  {
   "cell_type": "code",
   "execution_count": 36,
   "metadata": {},
   "outputs": [
    {
     "name": "stdout",
     "output_type": "stream",
     "text": [
      "Model: \"sequential_10\"\n",
      "_________________________________________________________________\n",
      " Layer (type)                Output Shape              Param #   \n",
      "=================================================================\n",
      " resizing_8 (Resizing)       (None, 32, 32, 1)         0         \n",
      "                                                                 \n",
      " conv2d_20 (Conv2D)          (None, 30, 30, 32)        320       \n",
      "                                                                 \n",
      " conv2d_21 (Conv2D)          (None, 27, 27, 32)        16416     \n",
      "                                                                 \n",
      " max_pooling2d_12 (MaxPoolin  (None, 13, 13, 32)       0         \n",
      " g2D)                                                            \n",
      "                                                                 \n",
      " dropout_20 (Dropout)        (None, 13, 13, 32)        0         \n",
      "                                                                 \n",
      " flatten_10 (Flatten)        (None, 5408)              0         \n",
      "                                                                 \n",
      " dense_20 (Dense)            (None, 128)               692352    \n",
      "                                                                 \n",
      " dropout_21 (Dropout)        (None, 128)               0         \n",
      "                                                                 \n",
      " dense_21 (Dense)            (None, 12)                1548      \n",
      "                                                                 \n",
      "=================================================================\n",
      "Total params: 710,636\n",
      "Trainable params: 710,636\n",
      "Non-trainable params: 0\n",
      "_________________________________________________________________\n"
     ]
    }
   ],
   "source": [
    "model = models.Sequential([\n",
    "    layers.Input(shape=[124, 129, 1]),\n",
    "    layers.Resizing(32, 32),\n",
    "    layers.Conv2D(32, 3, activation='gelu'),\n",
    "    layers.Conv2D(32, 4, activation='gelu'),\n",
    "    layers.MaxPooling2D(),\n",
    "    layers.Dropout(0.25),\n",
    "    layers.Flatten(),\n",
    "    layers.Dense(128, activation='gelu'),\n",
    "    layers.Dropout(0.5),\n",
    "    layers.Dense(12),\n",
    "])\n",
    "\n",
    "model.compile(\n",
    "    optimizer=tf.keras.optimizers.Adam(),\n",
    "    loss=tf.keras.losses.SparseCategoricalCrossentropy(from_logits=True),\n",
    "    metrics=['accuracy'],\n",
    ")\n",
    "\n",
    "model.summary()"
   ]
  },
  {
   "cell_type": "code",
   "execution_count": 37,
   "metadata": {},
   "outputs": [],
   "source": [
    "model.compile(\n",
    "    optimizer=tf.keras.optimizers.Adam(),\n",
    "    loss=tf.keras.losses.SparseCategoricalCrossentropy(from_logits=True),\n",
    "    metrics=['accuracy'],\n",
    ")"
   ]
  },
  {
   "cell_type": "code",
   "execution_count": 38,
   "metadata": {},
   "outputs": [
    {
     "name": "stdout",
     "output_type": "stream",
     "text": [
      "Epoch 1/30\n"
     ]
    },
    {
     "name": "stderr",
     "output_type": "stream",
     "text": [
      "2023-04-18 08:51:00.981487: E tensorflow/core/grappler/optimizers/meta_optimizer.cc:954] layout failed: INVALID_ARGUMENT: Size of values 0 does not match size of permutation 4 @ fanin shape insequential_10/dropout_20/dropout/SelectV2-2-TransposeNHWCToNCHW-LayoutOptimizer\n"
     ]
    },
    {
     "name": "stdout",
     "output_type": "stream",
     "text": [
      "804/804 [==============================] - 4s 3ms/step - loss: 0.9296 - accuracy: 0.7119 - val_loss: 2.2354 - val_accuracy: 0.3515\n",
      "Epoch 2/30\n",
      "804/804 [==============================] - 2s 3ms/step - loss: 0.5924 - accuracy: 0.8073 - val_loss: 1.7380 - val_accuracy: 0.4651\n",
      "Epoch 3/30\n",
      "804/804 [==============================] - 2s 3ms/step - loss: 0.4789 - accuracy: 0.8438 - val_loss: 1.6283 - val_accuracy: 0.5057\n",
      "Epoch 4/30\n",
      "804/804 [==============================] - 2s 3ms/step - loss: 0.4111 - accuracy: 0.8640 - val_loss: 1.3730 - val_accuracy: 0.5547\n",
      "Epoch 5/30\n",
      "804/804 [==============================] - 2s 3ms/step - loss: 0.3782 - accuracy: 0.8768 - val_loss: 1.4710 - val_accuracy: 0.5735\n",
      "Epoch 6/30\n",
      "804/804 [==============================] - 3s 3ms/step - loss: 0.3446 - accuracy: 0.8859 - val_loss: 1.5195 - val_accuracy: 0.5622\n",
      "Epoch 7/30\n",
      "804/804 [==============================] - 2s 3ms/step - loss: 0.3241 - accuracy: 0.8930 - val_loss: 1.4893 - val_accuracy: 0.5881\n",
      "Epoch 7: early stopping\n"
     ]
    }
   ],
   "source": [
    "EPOCHS = 30\n",
    "history = model.fit(\n",
    "    ds_train,\n",
    "    validation_data=ds_test,\n",
    "    epochs=EPOCHS,\n",
    "    callbacks=tf.keras.callbacks.EarlyStopping(verbose=1, patience=3),\n",
    ")"
   ]
  },
  {
   "cell_type": "code",
   "execution_count": 39,
   "metadata": {},
   "outputs": [
    {
     "name": "stderr",
     "output_type": "stream",
     "text": [
      "2023-04-18 08:55:27.554697: I tensorflow/core/common_runtime/executor.cc:1197] [/job:localhost/replica:0/task:0/device:CPU:0] (DEBUG INFO) Executor start aborting (this does not indicate an error and you can ignore this message): INVALID_ARGUMENT: Incompatible shapes at component 0: expected [?,61,65,1] but got [64,30,65,1].\n",
      "\t [[{{node IteratorGetNext}}]]\n",
      "2023-04-18 08:55:27.554975: I tensorflow/core/common_runtime/executor.cc:1197] [/job:localhost/replica:0/task:0/device:GPU:0] (DEBUG INFO) Executor start aborting (this does not indicate an error and you can ignore this message): INVALID_ARGUMENT: Incompatible shapes at component 0: expected [?,61,65,1] but got [64,30,65,1].\n",
      "\t [[{{node IteratorGetNext}}]]\n",
      "\t [[IteratorGetNext/_2]]\n"
     ]
    },
    {
     "ename": "InvalidArgumentError",
     "evalue": "Graph execution error:\n\nDetected at node 'IteratorGetNext' defined at (most recent call last):\n    File \"/usr/lib/python3.8/runpy.py\", line 194, in _run_module_as_main\n      return _run_code(code, main_globals, None,\n    File \"/usr/lib/python3.8/runpy.py\", line 87, in _run_code\n      exec(code, run_globals)\n    File \"/usr/local/lib/python3.8/dist-packages/ipykernel_launcher.py\", line 17, in <module>\n      app.launch_new_instance()\n    File \"/usr/local/lib/python3.8/dist-packages/traitlets/config/application.py\", line 1043, in launch_instance\n      app.start()\n    File \"/usr/local/lib/python3.8/dist-packages/ipykernel/kernelapp.py\", line 725, in start\n      self.io_loop.start()\n    File \"/usr/local/lib/python3.8/dist-packages/tornado/platform/asyncio.py\", line 215, in start\n      self.asyncio_loop.run_forever()\n    File \"/usr/lib/python3.8/asyncio/base_events.py\", line 570, in run_forever\n      self._run_once()\n    File \"/usr/lib/python3.8/asyncio/base_events.py\", line 1859, in _run_once\n      handle._run()\n    File \"/usr/lib/python3.8/asyncio/events.py\", line 81, in _run\n      self._context.run(self._callback, *self._args)\n    File \"/usr/local/lib/python3.8/dist-packages/ipykernel/kernelbase.py\", line 513, in dispatch_queue\n      await self.process_one()\n    File \"/usr/local/lib/python3.8/dist-packages/ipykernel/kernelbase.py\", line 502, in process_one\n      await dispatch(*args)\n    File \"/usr/local/lib/python3.8/dist-packages/ipykernel/kernelbase.py\", line 409, in dispatch_shell\n      await result\n    File \"/usr/local/lib/python3.8/dist-packages/ipykernel/kernelbase.py\", line 729, in execute_request\n      reply_content = await reply_content\n    File \"/usr/local/lib/python3.8/dist-packages/ipykernel/ipkernel.py\", line 422, in do_execute\n      res = shell.run_cell(\n    File \"/usr/local/lib/python3.8/dist-packages/ipykernel/zmqshell.py\", line 540, in run_cell\n      return super().run_cell(*args, **kwargs)\n    File \"/usr/local/lib/python3.8/dist-packages/IPython/core/interactiveshell.py\", line 3006, in run_cell\n      result = self._run_cell(\n    File \"/usr/local/lib/python3.8/dist-packages/IPython/core/interactiveshell.py\", line 3061, in _run_cell\n      result = runner(coro)\n    File \"/usr/local/lib/python3.8/dist-packages/IPython/core/async_helpers.py\", line 129, in _pseudo_sync_runner\n      coro.send(None)\n    File \"/usr/local/lib/python3.8/dist-packages/IPython/core/interactiveshell.py\", line 3266, in run_cell_async\n      has_raised = await self.run_ast_nodes(code_ast.body, cell_name,\n    File \"/usr/local/lib/python3.8/dist-packages/IPython/core/interactiveshell.py\", line 3445, in run_ast_nodes\n      if await self.run_code(code, result, async_=asy):\n    File \"/usr/local/lib/python3.8/dist-packages/IPython/core/interactiveshell.py\", line 3505, in run_code\n      exec(code_obj, self.user_global_ns, self.user_ns)\n    File \"/tmp/ipykernel_24359/1066239792.py\", line 1, in <module>\n      y_pred = model.predict(ds_test)\n    File \"/usr/local/lib/python3.8/dist-packages/keras/utils/traceback_utils.py\", line 65, in error_handler\n      return fn(*args, **kwargs)\n    File \"/usr/local/lib/python3.8/dist-packages/keras/engine/training.py\", line 2382, in predict\n      tmp_batch_outputs = self.predict_function(iterator)\n    File \"/usr/local/lib/python3.8/dist-packages/keras/engine/training.py\", line 2169, in predict_function\n      return step_function(self, iterator)\n    File \"/usr/local/lib/python3.8/dist-packages/keras/engine/training.py\", line 2154, in step_function\n      data = next(iterator)\nNode: 'IteratorGetNext'\nDetected at node 'IteratorGetNext' defined at (most recent call last):\n    File \"/usr/lib/python3.8/runpy.py\", line 194, in _run_module_as_main\n      return _run_code(code, main_globals, None,\n    File \"/usr/lib/python3.8/runpy.py\", line 87, in _run_code\n      exec(code, run_globals)\n    File \"/usr/local/lib/python3.8/dist-packages/ipykernel_launcher.py\", line 17, in <module>\n      app.launch_new_instance()\n    File \"/usr/local/lib/python3.8/dist-packages/traitlets/config/application.py\", line 1043, in launch_instance\n      app.start()\n    File \"/usr/local/lib/python3.8/dist-packages/ipykernel/kernelapp.py\", line 725, in start\n      self.io_loop.start()\n    File \"/usr/local/lib/python3.8/dist-packages/tornado/platform/asyncio.py\", line 215, in start\n      self.asyncio_loop.run_forever()\n    File \"/usr/lib/python3.8/asyncio/base_events.py\", line 570, in run_forever\n      self._run_once()\n    File \"/usr/lib/python3.8/asyncio/base_events.py\", line 1859, in _run_once\n      handle._run()\n    File \"/usr/lib/python3.8/asyncio/events.py\", line 81, in _run\n      self._context.run(self._callback, *self._args)\n    File \"/usr/local/lib/python3.8/dist-packages/ipykernel/kernelbase.py\", line 513, in dispatch_queue\n      await self.process_one()\n    File \"/usr/local/lib/python3.8/dist-packages/ipykernel/kernelbase.py\", line 502, in process_one\n      await dispatch(*args)\n    File \"/usr/local/lib/python3.8/dist-packages/ipykernel/kernelbase.py\", line 409, in dispatch_shell\n      await result\n    File \"/usr/local/lib/python3.8/dist-packages/ipykernel/kernelbase.py\", line 729, in execute_request\n      reply_content = await reply_content\n    File \"/usr/local/lib/python3.8/dist-packages/ipykernel/ipkernel.py\", line 422, in do_execute\n      res = shell.run_cell(\n    File \"/usr/local/lib/python3.8/dist-packages/ipykernel/zmqshell.py\", line 540, in run_cell\n      return super().run_cell(*args, **kwargs)\n    File \"/usr/local/lib/python3.8/dist-packages/IPython/core/interactiveshell.py\", line 3006, in run_cell\n      result = self._run_cell(\n    File \"/usr/local/lib/python3.8/dist-packages/IPython/core/interactiveshell.py\", line 3061, in _run_cell\n      result = runner(coro)\n    File \"/usr/local/lib/python3.8/dist-packages/IPython/core/async_helpers.py\", line 129, in _pseudo_sync_runner\n      coro.send(None)\n    File \"/usr/local/lib/python3.8/dist-packages/IPython/core/interactiveshell.py\", line 3266, in run_cell_async\n      has_raised = await self.run_ast_nodes(code_ast.body, cell_name,\n    File \"/usr/local/lib/python3.8/dist-packages/IPython/core/interactiveshell.py\", line 3445, in run_ast_nodes\n      if await self.run_code(code, result, async_=asy):\n    File \"/usr/local/lib/python3.8/dist-packages/IPython/core/interactiveshell.py\", line 3505, in run_code\n      exec(code_obj, self.user_global_ns, self.user_ns)\n    File \"/tmp/ipykernel_24359/1066239792.py\", line 1, in <module>\n      y_pred = model.predict(ds_test)\n    File \"/usr/local/lib/python3.8/dist-packages/keras/utils/traceback_utils.py\", line 65, in error_handler\n      return fn(*args, **kwargs)\n    File \"/usr/local/lib/python3.8/dist-packages/keras/engine/training.py\", line 2382, in predict\n      tmp_batch_outputs = self.predict_function(iterator)\n    File \"/usr/local/lib/python3.8/dist-packages/keras/engine/training.py\", line 2169, in predict_function\n      return step_function(self, iterator)\n    File \"/usr/local/lib/python3.8/dist-packages/keras/engine/training.py\", line 2154, in step_function\n      data = next(iterator)\nNode: 'IteratorGetNext'\n2 root error(s) found.\n  (0) INVALID_ARGUMENT:  Incompatible shapes at component 0: expected [?,61,65,1] but got [64,30,65,1].\n\t [[{{node IteratorGetNext}}]]\n\t [[IteratorGetNext/_2]]\n  (1) INVALID_ARGUMENT:  Incompatible shapes at component 0: expected [?,61,65,1] but got [64,30,65,1].\n\t [[{{node IteratorGetNext}}]]\n0 successful operations.\n0 derived errors ignored. [Op:__inference_predict_function_175961]",
     "output_type": "error",
     "traceback": [
      "\u001b[0;31m---------------------------------------------------------------------------\u001b[0m",
      "\u001b[0;31mInvalidArgumentError\u001b[0m                      Traceback (most recent call last)",
      "Cell \u001b[0;32mIn[39], line 1\u001b[0m\n\u001b[0;32m----> 1\u001b[0m y_pred \u001b[39m=\u001b[39m model\u001b[39m.\u001b[39;49mpredict(ds_test)\n\u001b[1;32m      2\u001b[0m y_pred \u001b[39m=\u001b[39m tf\u001b[39m.\u001b[39margmax(y_pred, axis\u001b[39m=\u001b[39m\u001b[39m1\u001b[39m)\n\u001b[1;32m      3\u001b[0m y_true \u001b[39m=\u001b[39m tf\u001b[39m.\u001b[39mconcat(\u001b[39mlist\u001b[39m(ds_test\u001b[39m.\u001b[39mmap(\u001b[39mlambda\u001b[39;00m s,lab: lab)), axis\u001b[39m=\u001b[39m\u001b[39m0\u001b[39m)\n",
      "File \u001b[0;32m/usr/local/lib/python3.8/dist-packages/keras/utils/traceback_utils.py:70\u001b[0m, in \u001b[0;36mfilter_traceback.<locals>.error_handler\u001b[0;34m(*args, **kwargs)\u001b[0m\n\u001b[1;32m     67\u001b[0m     filtered_tb \u001b[39m=\u001b[39m _process_traceback_frames(e\u001b[39m.\u001b[39m__traceback__)\n\u001b[1;32m     68\u001b[0m     \u001b[39m# To get the full stack trace, call:\u001b[39;00m\n\u001b[1;32m     69\u001b[0m     \u001b[39m# `tf.debugging.disable_traceback_filtering()`\u001b[39;00m\n\u001b[0;32m---> 70\u001b[0m     \u001b[39mraise\u001b[39;00m e\u001b[39m.\u001b[39mwith_traceback(filtered_tb) \u001b[39mfrom\u001b[39;00m \u001b[39mNone\u001b[39m\n\u001b[1;32m     71\u001b[0m \u001b[39mfinally\u001b[39;00m:\n\u001b[1;32m     72\u001b[0m     \u001b[39mdel\u001b[39;00m filtered_tb\n",
      "File \u001b[0;32m/usr/local/lib/python3.8/dist-packages/tensorflow/python/eager/execute.py:52\u001b[0m, in \u001b[0;36mquick_execute\u001b[0;34m(op_name, num_outputs, inputs, attrs, ctx, name)\u001b[0m\n\u001b[1;32m     50\u001b[0m \u001b[39mtry\u001b[39;00m:\n\u001b[1;32m     51\u001b[0m   ctx\u001b[39m.\u001b[39mensure_initialized()\n\u001b[0;32m---> 52\u001b[0m   tensors \u001b[39m=\u001b[39m pywrap_tfe\u001b[39m.\u001b[39mTFE_Py_Execute(ctx\u001b[39m.\u001b[39m_handle, device_name, op_name,\n\u001b[1;32m     53\u001b[0m                                       inputs, attrs, num_outputs)\n\u001b[1;32m     54\u001b[0m \u001b[39mexcept\u001b[39;00m core\u001b[39m.\u001b[39m_NotOkStatusException \u001b[39mas\u001b[39;00m e:\n\u001b[1;32m     55\u001b[0m   \u001b[39mif\u001b[39;00m name \u001b[39mis\u001b[39;00m \u001b[39mnot\u001b[39;00m \u001b[39mNone\u001b[39;00m:\n",
      "\u001b[0;31mInvalidArgumentError\u001b[0m: Graph execution error:\n\nDetected at node 'IteratorGetNext' defined at (most recent call last):\n    File \"/usr/lib/python3.8/runpy.py\", line 194, in _run_module_as_main\n      return _run_code(code, main_globals, None,\n    File \"/usr/lib/python3.8/runpy.py\", line 87, in _run_code\n      exec(code, run_globals)\n    File \"/usr/local/lib/python3.8/dist-packages/ipykernel_launcher.py\", line 17, in <module>\n      app.launch_new_instance()\n    File \"/usr/local/lib/python3.8/dist-packages/traitlets/config/application.py\", line 1043, in launch_instance\n      app.start()\n    File \"/usr/local/lib/python3.8/dist-packages/ipykernel/kernelapp.py\", line 725, in start\n      self.io_loop.start()\n    File \"/usr/local/lib/python3.8/dist-packages/tornado/platform/asyncio.py\", line 215, in start\n      self.asyncio_loop.run_forever()\n    File \"/usr/lib/python3.8/asyncio/base_events.py\", line 570, in run_forever\n      self._run_once()\n    File \"/usr/lib/python3.8/asyncio/base_events.py\", line 1859, in _run_once\n      handle._run()\n    File \"/usr/lib/python3.8/asyncio/events.py\", line 81, in _run\n      self._context.run(self._callback, *self._args)\n    File \"/usr/local/lib/python3.8/dist-packages/ipykernel/kernelbase.py\", line 513, in dispatch_queue\n      await self.process_one()\n    File \"/usr/local/lib/python3.8/dist-packages/ipykernel/kernelbase.py\", line 502, in process_one\n      await dispatch(*args)\n    File \"/usr/local/lib/python3.8/dist-packages/ipykernel/kernelbase.py\", line 409, in dispatch_shell\n      await result\n    File \"/usr/local/lib/python3.8/dist-packages/ipykernel/kernelbase.py\", line 729, in execute_request\n      reply_content = await reply_content\n    File \"/usr/local/lib/python3.8/dist-packages/ipykernel/ipkernel.py\", line 422, in do_execute\n      res = shell.run_cell(\n    File \"/usr/local/lib/python3.8/dist-packages/ipykernel/zmqshell.py\", line 540, in run_cell\n      return super().run_cell(*args, **kwargs)\n    File \"/usr/local/lib/python3.8/dist-packages/IPython/core/interactiveshell.py\", line 3006, in run_cell\n      result = self._run_cell(\n    File \"/usr/local/lib/python3.8/dist-packages/IPython/core/interactiveshell.py\", line 3061, in _run_cell\n      result = runner(coro)\n    File \"/usr/local/lib/python3.8/dist-packages/IPython/core/async_helpers.py\", line 129, in _pseudo_sync_runner\n      coro.send(None)\n    File \"/usr/local/lib/python3.8/dist-packages/IPython/core/interactiveshell.py\", line 3266, in run_cell_async\n      has_raised = await self.run_ast_nodes(code_ast.body, cell_name,\n    File \"/usr/local/lib/python3.8/dist-packages/IPython/core/interactiveshell.py\", line 3445, in run_ast_nodes\n      if await self.run_code(code, result, async_=asy):\n    File \"/usr/local/lib/python3.8/dist-packages/IPython/core/interactiveshell.py\", line 3505, in run_code\n      exec(code_obj, self.user_global_ns, self.user_ns)\n    File \"/tmp/ipykernel_24359/1066239792.py\", line 1, in <module>\n      y_pred = model.predict(ds_test)\n    File \"/usr/local/lib/python3.8/dist-packages/keras/utils/traceback_utils.py\", line 65, in error_handler\n      return fn(*args, **kwargs)\n    File \"/usr/local/lib/python3.8/dist-packages/keras/engine/training.py\", line 2382, in predict\n      tmp_batch_outputs = self.predict_function(iterator)\n    File \"/usr/local/lib/python3.8/dist-packages/keras/engine/training.py\", line 2169, in predict_function\n      return step_function(self, iterator)\n    File \"/usr/local/lib/python3.8/dist-packages/keras/engine/training.py\", line 2154, in step_function\n      data = next(iterator)\nNode: 'IteratorGetNext'\nDetected at node 'IteratorGetNext' defined at (most recent call last):\n    File \"/usr/lib/python3.8/runpy.py\", line 194, in _run_module_as_main\n      return _run_code(code, main_globals, None,\n    File \"/usr/lib/python3.8/runpy.py\", line 87, in _run_code\n      exec(code, run_globals)\n    File \"/usr/local/lib/python3.8/dist-packages/ipykernel_launcher.py\", line 17, in <module>\n      app.launch_new_instance()\n    File \"/usr/local/lib/python3.8/dist-packages/traitlets/config/application.py\", line 1043, in launch_instance\n      app.start()\n    File \"/usr/local/lib/python3.8/dist-packages/ipykernel/kernelapp.py\", line 725, in start\n      self.io_loop.start()\n    File \"/usr/local/lib/python3.8/dist-packages/tornado/platform/asyncio.py\", line 215, in start\n      self.asyncio_loop.run_forever()\n    File \"/usr/lib/python3.8/asyncio/base_events.py\", line 570, in run_forever\n      self._run_once()\n    File \"/usr/lib/python3.8/asyncio/base_events.py\", line 1859, in _run_once\n      handle._run()\n    File \"/usr/lib/python3.8/asyncio/events.py\", line 81, in _run\n      self._context.run(self._callback, *self._args)\n    File \"/usr/local/lib/python3.8/dist-packages/ipykernel/kernelbase.py\", line 513, in dispatch_queue\n      await self.process_one()\n    File \"/usr/local/lib/python3.8/dist-packages/ipykernel/kernelbase.py\", line 502, in process_one\n      await dispatch(*args)\n    File \"/usr/local/lib/python3.8/dist-packages/ipykernel/kernelbase.py\", line 409, in dispatch_shell\n      await result\n    File \"/usr/local/lib/python3.8/dist-packages/ipykernel/kernelbase.py\", line 729, in execute_request\n      reply_content = await reply_content\n    File \"/usr/local/lib/python3.8/dist-packages/ipykernel/ipkernel.py\", line 422, in do_execute\n      res = shell.run_cell(\n    File \"/usr/local/lib/python3.8/dist-packages/ipykernel/zmqshell.py\", line 540, in run_cell\n      return super().run_cell(*args, **kwargs)\n    File \"/usr/local/lib/python3.8/dist-packages/IPython/core/interactiveshell.py\", line 3006, in run_cell\n      result = self._run_cell(\n    File \"/usr/local/lib/python3.8/dist-packages/IPython/core/interactiveshell.py\", line 3061, in _run_cell\n      result = runner(coro)\n    File \"/usr/local/lib/python3.8/dist-packages/IPython/core/async_helpers.py\", line 129, in _pseudo_sync_runner\n      coro.send(None)\n    File \"/usr/local/lib/python3.8/dist-packages/IPython/core/interactiveshell.py\", line 3266, in run_cell_async\n      has_raised = await self.run_ast_nodes(code_ast.body, cell_name,\n    File \"/usr/local/lib/python3.8/dist-packages/IPython/core/interactiveshell.py\", line 3445, in run_ast_nodes\n      if await self.run_code(code, result, async_=asy):\n    File \"/usr/local/lib/python3.8/dist-packages/IPython/core/interactiveshell.py\", line 3505, in run_code\n      exec(code_obj, self.user_global_ns, self.user_ns)\n    File \"/tmp/ipykernel_24359/1066239792.py\", line 1, in <module>\n      y_pred = model.predict(ds_test)\n    File \"/usr/local/lib/python3.8/dist-packages/keras/utils/traceback_utils.py\", line 65, in error_handler\n      return fn(*args, **kwargs)\n    File \"/usr/local/lib/python3.8/dist-packages/keras/engine/training.py\", line 2382, in predict\n      tmp_batch_outputs = self.predict_function(iterator)\n    File \"/usr/local/lib/python3.8/dist-packages/keras/engine/training.py\", line 2169, in predict_function\n      return step_function(self, iterator)\n    File \"/usr/local/lib/python3.8/dist-packages/keras/engine/training.py\", line 2154, in step_function\n      data = next(iterator)\nNode: 'IteratorGetNext'\n2 root error(s) found.\n  (0) INVALID_ARGUMENT:  Incompatible shapes at component 0: expected [?,61,65,1] but got [64,30,65,1].\n\t [[{{node IteratorGetNext}}]]\n\t [[IteratorGetNext/_2]]\n  (1) INVALID_ARGUMENT:  Incompatible shapes at component 0: expected [?,61,65,1] but got [64,30,65,1].\n\t [[{{node IteratorGetNext}}]]\n0 successful operations.\n0 derived errors ignored. [Op:__inference_predict_function_175961]"
     ]
    }
   ],
   "source": [
    "y_pred = model.predict(ds_test)\n",
    "y_pred = tf.argmax(y_pred, axis=1)\n",
    "y_true = tf.concat(list(ds_test.map(lambda s,lab: lab)), axis=0)\n",
    "confusion_mtx = tf.math.confusion_matrix(y_true, y_pred)\n",
    "plt.figure(figsize=(10, 8))\n",
    "sns.heatmap(confusion_mtx,\n",
    "            annot=True, fmt='g')\n",
    "plt.xlabel('Prediction')\n",
    "plt.ylabel('Label')\n",
    "plt.show()\n"
   ]
  }
 ],
 "metadata": {
  "kernelspec": {
   "display_name": "Python 3",
   "language": "python",
   "name": "python3"
  },
  "language_info": {
   "codemirror_mode": {
    "name": "ipython",
    "version": 3
   },
   "file_extension": ".py",
   "mimetype": "text/x-python",
   "name": "python",
   "nbconvert_exporter": "python",
   "pygments_lexer": "ipython3",
   "version": "3.8.10"
  },
  "orig_nbformat": 4
 },
 "nbformat": 4,
 "nbformat_minor": 2
}
